Workbook

Sheet Summary
A1: Vonnue Cup – Entries Summary
A2: Counts are live formulas on the 'All Entries' sheet (entries = singles players / doubles pairs / squad members).
A4: Sport | B4: Event | C4: Division | D4: Team 1 – Rajarajeshwari United | E4: Team 2 – Jeem Boom Baa | F4: Team 3 – Dr. D | G4: Team 4 – Thoofan | H4: Team 5 – Dhurandhar | I4: Team 6 – Aaram Thamburan | J4: Total
A5: Badminton | B5: Singles | C5: Men | D5: =COUNTIFS('All Entries'!$B$2:$B$156,D$4,'All Entries'!$C$2:$C$156,$A5,'All Entries'!$E$2:$E$156,$B5,'All Entries'!$D$2:$D$156,$C5) | E5: =COUNTIFS('All Entries'!$B$2:$B$156,E$4,'All Entries'!$C$2:$C$156,$A5,'All Entries'!$E$2:$E$156,$B5,'All Entries'!$D$2:$D$156,$C5) | F5: =COUNTIFS('All Entries'!$B$2:$B$156,F$4,'All Entries'!$C$2:$C$156,$A5,'All Entries'!$E$2:$E$156,$B5,'All Entries'!$D$2:$D$156,$C5) | G5: =COUNTIFS('All Entries'!$B$2:$B$156,G$4,'All Entries'!$C$2:$C$156,$A5,'All Entries'!$E$2:$E$156,$B5,'All Entries'!$D$2:$D$156,$C5) | H5: =COUNTIFS('All Entries'!$B$2:$B$156,H$4,'All Entries'!$C$2:$C$156,$A5,'All Entries'!$E$2:$E$156,$B5,'All Entries'!$D$2:$D$156,$C5) | I5: =COUNTIFS('All Entries'!$B$2:$B$156,I$4,'All Entries'!$C$2:$C$156,$A5,'All Entries'!$E$2:$E$156,$B5,'All Entries'!$D$2:$D$156,$C5) | J5: =SUM(D5:I5)
A6: Badminton | B6: Singles | C6: Women | D6: =COUNTIFS('All Entries'!$B$2:$B$156,D$4,'All Entries'!$C$2:$C$156,$A6,'All Entries'!$E$2:$E$156,$B6,'All Entries'!$D$2:$D$156,$C6) | E6: =COUNTIFS('All Entries'!$B$2:$B$156,E$4,'All Entries'!$C$2:$C$156,$A6,'All Entries'!$E$2:$E$156,$B6,'All Entries'!$D$2:$D$156,$C6) | F6: =COUNTIFS('All Entries'!$B$2:$B$156,F$4,'All Entries'!$C$2:$C$156,$A6,'All Entries'!$E$2:$E$156,$B6,'All Entries'!$D$2:$D$156,$C6) | G6: =COUNTIFS('All Entries'!$B$2:$B$156,G$4,'All Entries'!$C$2:$C$156,$A6,'All Entries'!$E$2:$E$156,$B6,'All Entries'!$D$2:$D$156,$C6) | H6: =COUNTIFS('All Entries'!$B$2:$B$156,H$4,'All Entries'!$C$2:$C$156,$A6,'All Entries'!$E$2:$E$156,$B6,'All Entries'!$D$2:$D$156,$C6) | I6: =COUNTIFS('All Entries'!$B$2:$B$156,I$4,'All Entries'!$C$2:$C$156,$A6,'All Entries'!$E$2:$E$156,$B6,'All Entries'!$D$2:$D$156,$C6) | J6: =SUM(D6:I6)
A7: Badminton | B7: Doubles | C7: Men | D7: =COUNTIFS('All Entries'!$B$2:$B$156,D$4,'All Entries'!$C$2:$C$156,$A7,'All Entries'!$E$2:$E$156,$B7,'All Entries'!$D$2:$D$156,$C7) | E7: =COUNTIFS('All Entries'!$B$2:$B$156,E$4,'All Entries'!$C$2:$C$156,$A7,'All Entries'!$E$2:$E$156,$B7,'All Entries'!$D$2:$D$156,$C7) | F7: =COUNTIFS('All Entries'!$B$2:$B$156,F$4,'All Entries'!$C$2:$C$156,$A7,'All Entries'!$E$2:$E$156,$B7,'All Entries'!$D$2:$D$156,$C7) | G7: =COUNTIFS('All Entries'!$B$2:$B$156,G$4,'All Entries'!$C$2:$C$156,$A7,'All Entries'!$E$2:$E$156,$B7,'All Entries'!$D$2:$D$156,$C7) | H7: =COUNTIFS('All Entries'!$B$2:$B$156,H$4,'All Entries'!$C$2:$C$156,$A7,'All Entries'!$E$2:$E$156,$B7,'All Entries'!$D$2:$D$156,$C7) | I7: =COUNTIFS('All Entries'!$B$2:$B$156,I$4,'All Entries'!$C$2:$C$156,$A7,'All Entries'!$E$2:$E$156,$B7,'All Entries'!$D$2:$D$156,$C7) | J7: =SUM(D7:I7)
A8: Badminton | B8: Doubles | C8: Women | D8: =COUNTIFS('All Entries'!$B$2:$B$156,D$4,'All Entries'!$C$2:$C$156,$A8,'All Entries'!$E$2:$E$156,$B8,'All Entries'!$D$2:$D$156,$C8) | E8: =COUNTIFS('All Entries'!$B$2:$B$156,E$4,'All Entries'!$C$2:$C$156,$A8,'All Entries'!$E$2:$E$156,$B8,'All Entries'!$D$2:$D$156,$C8) | F8: =COUNTIFS('All Entries'!$B$2:$B$156,F$4,'All Entries'!$C$2:$C$156,$A8,'All Entries'!$E$2:$E$156,$B8,'All Entries'!$D$2:$D$156,$C8) | G8: =COUNTIFS('All Entries'!$B$2:$B$156,G$4,'All Entries'!$C$2:$C$156,$A8,'All Entries'!$E$2:$E$156,$B8,'All Entries'!$D$2:$D$156,$C8) | H8: =COUNTIFS('All Entries'!$B$2:$B$156,H$4,'All Entries'!$C$2:$C$156,$A8,'All Entries'!$E$2:$E$156,$B8,'All Entries'!$D$2:$D$156,$C8) | I8: =COUNTIFS('All Entries'!$B$2:$B$156,I$4,'All Entries'!$C$2:$C$156,$A8,'All Entries'!$E$2:$E$156,$B8,'All Entries'!$D$2:$D$156,$C8) | J8: =SUM(D8:I8)
A9: Table Tennis | B9: Singles | C9: Men | D9: =COUNTIFS('All Entries'!$B$2:$B$156,D$4,'All Entries'!$C$2:$C$156,$A9,'All Entries'!$E$2:$E$156,$B9,'All Entries'!$D$2:$D$156,$C9) | E9: =COUNTIFS('All Entries'!$B$2:$B$156,E$4,'All Entries'!$C$2:$C$156,$A9,'All Entries'!$E$2:$E$156,$B9,'All Entries'!$D$2:$D$156,$C9) | F9: =COUNTIFS('All Entries'!$B$2:$B$156,F$4,'All Entries'!$C$2:$C$156,$A9,'All Entries'!$E$2:$E$156,$B9,'All Entries'!$D$2:$D$156,$C9) | G9: =COUNTIFS('All Entries'!$B$2:$B$156,G$4,'All Entries'!$C$2:$C$156,$A9,'All Entries'!$E$2:$E$156,$B9,'All Entries'!$D$2:$D$156,$C9) | H9: =COUNTIFS('All Entries'!$B$2:$B$156,H$4,'All Entries'!$C$2:$C$156,$A9,'All Entries'!$E$2:$E$156,$B9,'All Entries'!$D$2:$D$156,$C9) | I9: =COUNTIFS('All Entries'!$B$2:$B$156,I$4,'All Entries'!$C$2:$C$156,$A9,'All Entries'!$E$2:$E$156,$B9,'All Entries'!$D$2:$D$156,$C9) | J9: =SUM(D9:I9)
A10: Table Tennis | B10: Singles | C10: Women | D10: =COUNTIFS('All Entries'!$B$2:$B$156,D$4,'All Entries'!$C$2:$C$156,$A10,'All Entries'!$E$2:$E$156,$B10,'All Entries'!$D$2:$D$156,$C10) | E10: =COUNTIFS('All Entries'!$B$2:$B$156,E$4,'All Entries'!$C$2:$C$156,$A10,'All Entries'!$E$2:$E$156,$B10,'All Entries'!$D$2:$D$156,$C10) | F10: =COUNTIFS('All Entries'!$B$2:$B$156,F$4,'All Entries'!$C$2:$C$156,$A10,'All Entries'!$E$2:$E$156,$B10,'All Entries'!$D$2:$D$156,$C10) | G10: =COUNTIFS('All Entries'!$B$2:$B$156,G$4,'All Entries'!$C$2:$C$156,$A10,'All Entries'!$E$2:$E$156,$B10,'All Entries'!$D$2:$D$156,$C10) | H10: =COUNTIFS('All Entries'!$B$2:$B$156,H$4,'All Entries'!$C$2:$C$156,$A10,'All Entries'!$E$2:$E$156,$B10,'All Entries'!$D$2:$D$156,$C10) | I10: =COUNTIFS('All Entries'!$B$2:$B$156,I$4,'All Entries'!$C$2:$C$156,$A10,'All Entries'!$E$2:$E$156,$B10,'All Entries'!$D$2:$D$156,$C10) | J10: =SUM(D10:I10)
A11: Table Tennis | B11: Doubles | C11: Men | D11: =COUNTIFS('All Entries'!$B$2:$B$156,D$4,'All Entries'!$C$2:$C$156,$A11,'All Entries'!$E$2:$E$156,$B11,'All Entries'!$D$2:$D$156,$C11) | E11: =COUNTIFS('All Entries'!$B$2:$B$156,E$4,'All Entries'!$C$2:$C$156,$A11,'All Entries'!$E$2:$E$156,$B11,'All Entries'!$D$2:$D$156,$C11) | F11: =COUNTIFS('All Entries'!$B$2:$B$156,F$4,'All Entries'!$C$2:$C$156,$A11,'All Entries'!$E$2:$E$156,$B11,'All Entries'!$D$2:$D$156,$C11) | G11: =COUNTIFS('All Entries'!$B$2:$B$156,G$4,'All Entries'!$C$2:$C$156,$A11,'All Entries'!$E$2:$E$156,$B11,'All Entries'!$D$2:$D$156,$C11) | H11: =COUNTIFS('All Entries'!$B$2:$B$156,H$4,'All Entries'!$C$2:$C$156,$A11,'All Entries'!$E$2:$E$156,$B11,'All Entries'!$D$2:$D$156,$C11) | I11: =COUNTIFS('All Entries'!$B$2:$B$156,I$4,'All Entries'!$C$2:$C$156,$A11,'All Entries'!$E$2:$E$156,$B11,'All Entries'!$D$2:$D$156,$C11) | J11: =SUM(D11:I11)
A12: Table Tennis | B12: Doubles | C12: Women | D12: =COUNTIFS('All Entries'!$B$2:$B$156,D$4,'All Entries'!$C$2:$C$156,$A12,'All Entries'!$E$2:$E$156,$B12,'All Entries'!$D$2:$D$156,$C12) | E12: =COUNTIFS('All Entries'!$B$2:$B$156,E$4,'All Entries'!$C$2:$C$156,$A12,'All Entries'!$E$2:$E$156,$B12,'All Entries'!$D$2:$D$156,$C12) | F12: =COUNTIFS('All Entries'!$B$2:$B$156,F$4,'All Entries'!$C$2:$C$156,$A12,'All Entries'!$E$2:$E$156,$B12,'All Entries'!$D$2:$D$156,$C12) | G12: =COUNTIFS('All Entries'!$B$2:$B$156,G$4,'All Entries'!$C$2:$C$156,$A12,'All Entries'!$E$2:$E$156,$B12,'All Entries'!$D$2:$D$156,$C12) | H12: =COUNTIFS('All Entries'!$B$2:$B$156,H$4,'All Entries'!$C$2:$C$156,$A12,'All Entries'!$E$2:$E$156,$B12,'All Entries'!$D$2:$D$156,$C12) | I12: =COUNTIFS('All Entries'!$B$2:$B$156,I$4,'All Entries'!$C$2:$C$156,$A12,'All Entries'!$E$2:$E$156,$B12,'All Entries'!$D$2:$D$156,$C12) | J12: =SUM(D12:I12)
A13: Carrom | B13: Doubles | C13: Open | D13: =COUNTIFS('All Entries'!$B$2:$B$156,D$4,'All Entries'!$C$2:$C$156,$A13,'All Entries'!$E$2:$E$156,$B13,'All Entries'!$D$2:$D$156,$C13) | E13: =COUNTIFS('All Entries'!$B$2:$B$156,E$4,'All Entries'!$C$2:$C$156,$A13,'All Entries'!$E$2:$E$156,$B13,'All Entries'!$D$2:$D$156,$C13) | F13: =COUNTIFS('All Entries'!$B$2:$B$156,F$4,'All Entries'!$C$2:$C$156,$A13,'All Entries'!$E$2:$E$156,$B13,'All Entries'!$D$2:$D$156,$C13) | G13: =COUNTIFS('All Entries'!$B$2:$B$156,G$4,'All Entries'!$C$2:$C$156,$A13,'All Entries'!$E$2:$E$156,$B13,'All Entries'!$D$2:$D$156,$C13) | H13: =COUNTIFS('All Entries'!$B$2:$B$156,H$4,'All Entries'!$C$2:$C$156,$A13,'All Entries'!$E$2:$E$156,$B13,'All Entries'!$D$2:$D$156,$C13) | I13: =COUNTIFS('All Entries'!$B$2:$B$156,I$4,'All Entries'!$C$2:$C$156,$A13,'All Entries'!$E$2:$E$156,$B13,'All Entries'!$D$2:$D$156,$C13) | J13: =SUM(D13:I13)
A14: Chess | B14: Singles | C14: Men | D14: =COUNTIFS('All Entries'!$B$2:$B$156,D$4,'All Entries'!$C$2:$C$156,$A14,'All Entries'!$E$2:$E$156,$B14,'All Entries'!$D$2:$D$156,$C14) | E14: =COUNTIFS('All Entries'!$B$2:$B$156,E$4,'All Entries'!$C$2:$C$156,$A14,'All Entries'!$E$2:$E$156,$B14,'All Entries'!$D$2:$D$156,$C14) | F14: =COUNTIFS('All Entries'!$B$2:$B$156,F$4,'All Entries'!$C$2:$C$156,$A14,'All Entries'!$E$2:$E$156,$B14,'All Entries'!$D$2:$D$156,$C14) | G14: =COUNTIFS('All Entries'!$B$2:$B$156,G$4,'All Entries'!$C$2:$C$156,$A14,'All Entries'!$E$2:$E$156,$B14,'All Entries'!$D$2:$D$156,$C14) | H14: =COUNTIFS('All Entries'!$B$2:$B$156,H$4,'All Entries'!$C$2:$C$156,$A14,'All Entries'!$E$2:$E$156,$B14,'All Entries'!$D$2:$D$156,$C14) | I14: =COUNTIFS('All Entries'!$B$2:$B$156,I$4,'All Entries'!$C$2:$C$156,$A14,'All Entries'!$E$2:$E$156,$B14,'All Entries'!$D$2:$D$156,$C14) | J14: =SUM(D14:I14)
A15: Chess | B15: Singles | C15: Women | D15: =COUNTIFS('All Entries'!$B$2:$B$156,D$4,'All Entries'!$C$2:$C$156,$A15,'All Entries'!$E$2:$E$156,$B15,'All Entries'!$D$2:$D$156,$C15) | E15: =COUNTIFS('All Entries'!$B$2:$B$156,E$4,'All Entries'!$C$2:$C$156,$A15,'All Entries'!$E$2:$E$156,$B15,'All Entries'!$D$2:$D$156,$C15) | F15: =COUNTIFS('All Entries'!$B$2:$B$156,F$4,'All Entries'!$C$2:$C$156,$A15,'All Entries'!$E$2:$E$156,$B15,'All Entries'!$D$2:$D$156,$C15) | G15: =COUNTIFS('All Entries'!$B$2:$B$156,G$4,'All Entries'!$C$2:$C$156,$A15,'All Entries'!$E$2:$E$156,$B15,'All Entries'!$D$2:$D$156,$C15) | H15: =COUNTIFS('All Entries'!$B$2:$B$156,H$4,'All Entries'!$C$2:$C$156,$A15,'All Entries'!$E$2:$E$156,$B15,'All Entries'!$D$2:$D$156,$C15) | I15: =COUNTIFS('All Entries'!$B$2:$B$156,I$4,'All Entries'!$C$2:$C$156,$A15,'All Entries'!$E$2:$E$156,$B15,'All Entries'!$D$2:$D$156,$C15) | J15: =SUM(D15:I15)
A16: Chess | B16: Singles | C16: Open | D16: =COUNTIFS('All Entries'!$B$2:$B$156,D$4,'All Entries'!$C$2:$C$156,$A16,'All Entries'!$E$2:$E$156,$B16,'All Entries'!$D$2:$D$156,$C16) | E16: =COUNTIFS('All Entries'!$B$2:$B$156,E$4,'All Entries'!$C$2:$C$156,$A16,'All Entries'!$E$2:$E$156,$B16,'All Entries'!$D$2:$D$156,$C16) | F16: =COUNTIFS('All Entries'!$B$2:$B$156,F$4,'All Entries'!$C$2:$C$156,$A16,'All Entries'!$E$2:$E$156,$B16,'All Entries'!$D$2:$D$156,$C16) | G16: =COUNTIFS('All Entries'!$B$2:$B$156,G$4,'All Entries'!$C$2:$C$156,$A16,'All Entries'!$E$2:$E$156,$B16,'All Entries'!$D$2:$D$156,$C16) | H16: =COUNTIFS('All Entries'!$B$2:$B$156,H$4,'All Entries'!$C$2:$C$156,$A16,'All Entries'!$E$2:$E$156,$B16,'All Entries'!$D$2:$D$156,$C16) | I16: =COUNTIFS('All Entries'!$B$2:$B$156,I$4,'All Entries'!$C$2:$C$156,$A16,'All Entries'!$E$2:$E$156,$B16,'All Entries'!$D$2:$D$156,$C16) | J16: =SUM(D16:I16)
A17: Total entries | D17: =SUM(D5:D16) | E17: =SUM(E5:E16) | F17: =SUM(F5:F16) | G17: =SUM(G5:G16) | H17: =SUM(H5:H16) | I17: =SUM(I5:I16) | J17: =SUM(J5:J16)
A18: Unique participants | D18: 18 | E18: 19 | F18: 17 | G18: 16 | H18: 12 | I18: 19
A19: Unique participants = distinct names per team as spelled in the sheet (hardcoded count, computed when the sheet was built).
A20: Cricket and Football are team events – individual player lists are not tracked in this sheet.

Sheet All Entries
A1: # | B1: Team | C1: Sport | D1: Division | E1: Event | F1: Player 1 | G1: Player 2 | H1: Entry
A2: 1 | B2: Team 1 – Rajarajeshwari United | C2: Badminton | D2: Men | E2: Singles | F2: Amit | H2: =IF(G2="",F2,F2&" & "&G2)
A3: 2 | B3: Team 1 – Rajarajeshwari United | C3: Badminton | D3: Men | E3: Singles | F3: Joyel | H3: =IF(G3="",F3,F3&" & "&G3)
A4: 3 | B4: Team 2 – Jeem Boom Baa | C4: Badminton | D4: Men | E4: Singles | F4: Gokul | H4: =IF(G4="",F4,F4&" & "&G4)
A5: 4 | B5: Team 2 – Jeem Boom Baa | C5: Badminton | D5: Men | E5: Singles | F5: Amal | H5: =IF(G5="",F5,F5&" & "&G5)
A6: 5 | B6: Team 3 – Dr. D | C6: Badminton | D6: Men | E6: Singles | F6: Kevin | H6: =IF(G6="",F6,F6&" & "&G6)
A7: 6 | B7: Team 3 – Dr. D | C7: Badminton | D7: Men | E7: Singles | F7: Adwaith | H7: =IF(G7="",F7,F7&" & "&G7)
A8: 7 | B8: Team 4 – Thoofan | C8: Badminton | D8: Men | E8: Singles | F8: Sahil M I | H8: =IF(G8="",F8,F8&" & "&G8)
A9: 8 | B9: Team 4 – Thoofan | C9: Badminton | D9: Men | E9: Singles | F9: Rajeesh C V | H9: =IF(G9="",F9,F9&" & "&G9)
A10: 9 | B10: Team 5 – Dhurandhar | C10: Badminton | D10: Men | E10: Singles | F10: Adhith Vinoj | H10: =IF(G10="",F10,F10&" & "&G10)
A11: 10 | B11: Team 5 – Dhurandhar | C11: Badminton | D11: Men | E11: Singles | F11: Nidheesh P V | H11: =IF(G11="",F11,F11&" & "&G11)
A12: 11 | B12: Team 6 – Aaram Thamburan | C12: Badminton | D12: Men | E12: Singles | F12: Joel | H12: =IF(G12="",F12,F12&" & "&G12)
A13: 12 | B13: Team 6 – Aaram Thamburan | C13: Badminton | D13: Men | E13: Singles | F13: Jayesh | H13: =IF(G13="",F13,F13&" & "&G13)
... A25: 24 | B25: Team 6 – Aaram Thamburan | C25: Badminton | D25: Women | E25: Singles | F25: Akshaya | H25: =IF(G25="",F25,F25&" & "&G25)
A26: 25 | B26: Team 1 – Rajarajeshwari United | C26: Badminton | D26: Men | E26: Doubles | F26: Amit | G26: Rishikesh | H26: =IF(G26="",F26,F26&" & "&G26)
A27: 26 | B27: Team 1 – Rajarajeshwari United | C27: Badminton | D27: Men | E27: Doubles | F27: Joyel | G27: Jithu | H27: =IF(G27="",F27,F27&" & "&G27)
A28: 27 | B28: Team 2 – Jeem Boom Baa | C28: Badminton | D28: Men | E28: Doubles | F28: Gokul | G28: Amal | H28: =IF(G28="",F28,F28&" & "&G28)
A29: 28 | B29: Team 2 – Jeem Boom Baa | C29: Badminton | D29: Men | E29: Doubles | F29: Thomas | G29: Sravan | H29: =IF(G29="",F29,F29&" & "&G29)
A30: 29 | B30: Team 3 – Dr. D | C30: Badminton | D30: Men | E30: Doubles | F30: Ashmil | G30: Jerishab | H30: =IF(G30="",F30,F30&" & "&G30)
A31: 30 | B31: Team 3 – Dr. D | C31: Badminton | D31: Men | E31: Doubles | F31: Rithik | G31: Jerin | H31: =IF(G31="",F31,F31&" & "&G31)
A32: 31 | B32: Team 4 – Thoofan | C32: Badminton | D32: Men | E32: Doubles | F32: Sahil M I | G32: Rajeesh C V | H32: =IF(G32="",F32,F32&" & "&G32)
A33: 32 | B33: Team 4 – Thoofan | C33: Badminton | D33: Men | E33: Doubles | F33: Don | G33: Gautham | H33: =IF(G33="",F33,F33&" & "&G33)
A34: 33 | B34: Team 5 – Dhurandhar | C34: Badminton | D34: Men | E34: Doubles | F34: Nidheesh P V | G34: Adhith Vinoj | H34: =IF(G34="",F34,F34&" & "&G34)
A35: 34 | B35: Team 6 – Aaram Thamburan | C35: Badminton | D35: Men | E35: Doubles | F35: Joel | G35: Jayesh | H35: =IF(G35="",F35,F35&" & "&G35)
A36: 35 | B36: Team 6 – Aaram Thamburan | C36: Badminton | D36: Men | E36: Doubles | F36: Sharan | G36: Musthaq | H36: =IF(G36="",F36,F36&" & "&G36)
A37: 36 | B37: Team 1 – Rajarajeshwari United | C37: Badminton | D37: Women | E37: Doubles | F37: Neethu | G37: Nivya Mathew | H37: =IF(G37="",F37,F37&" & "&G37)
... A47: 46 | B47: Team 6 – Aaram Thamburan | C47: Badminton | D47: Women | E47: Doubles | F47: Ashna | G47: Akhila / Athira | H47: =IF(G47="",F47,F47&" & "&G47)
A48: 47 | B48: Team 1 – Rajarajeshwari United | C48: Table Tennis | D48: Men | E48: Singles | F48: Rishikesh | H48: =IF(G48="",F48,F48&" & "&G48)
A49: 48 | B49: Team 1 – Rajarajeshwari United | C49: Table Tennis | D49: Men | E49: Singles | F49: Amit | H49: =IF(G49="",F49,F49&" & "&G49)
A50: 49 | B50: Team 1 – Rajarajeshwari United | C50: Table Tennis | D50: Men | E50: Singles | F50: Bilal | H50: =IF(G50="",F50,F50&" & "&G50)
A51: 50 | B51: Team 1 – Rajarajeshwari United | C51: Table Tennis | D51: Men | E51: Singles | F51: Deekshith | H51: =IF(G51="",F51,F51&" & "&G51)
A52: 51 | B52: Team 1 – Rajarajeshwari United | C52: Table Tennis | D52: Men | E52: Singles | F52: Joyel | H52: =IF(G52="",F52,F52&" & "&G52)
A53: 52 | B53: Team 1 – Rajarajeshwari United | C53: Table Tennis | D53: Men | E53: Singles | F53: Vidhu | H53: =IF(G53="",F53,F53&" & "&G53)
A54: 53 | B54: Team 2 – Jeem Boom Baa | C54: Table Tennis | D54: Men | E54: Singles | F54: Ray | H54: =IF(G54="",F54,F54&" & "&G54)
A55: 54 | B55: Team 2 – Jeem Boom Baa | C55: Table Tennis | D55: Men | E55: Singles | F55: Thomas | H55: =IF(G55="",F55,F55&" & "&G55)
A56: 55 | B56: Team 3 – Dr. D | C56: Table Tennis | D56: Men | E56: Singles | F56: Rithik | H56: =IF(G56="",F56,F56&" & "&G56)
A57: 56 | B57: Team 3 – Dr. D | C57: Table Tennis | D57: Men | E57: Singles | F57: Alwin | H57: =IF(G57="",F57,F57&" & "&G57)
A58: 57 | B58: Team 3 – Dr. D | C58: Table Tennis | D58: Men | E58: Singles | F58: Adwaith | H58: =IF(G58="",F58,F58&" & "&G58)
A59: 58 | B59: Team 3 – Dr. D | C59: Table Tennis | D59: Men | E59: Singles | F59: Prajith | H59: =IF(G59="",F59,F59&" & "&G59)
... A77: 76 | B77: Team 6 – Aaram Thamburan | C77: Table Tennis | D77: Women | E77: Singles | F77: Ashna | H77: =IF(G77="",F77,F77&" & "&G77)
...

Sheet Badminton
A1: Badminton – Entries
A3: Men’s Singles
A4: # | B4: Team | C4: Player 1 | E4: Notes
A5: 1 | B5: Team 1 – Rajarajeshwari United | C5: Amit
A6: 2 | B6: Team 1 – Rajarajeshwari United | C6: Joyel
A7: 3 | B7: Team 2 – Jeem Boom Baa | C7: Gokul
A8: 4 | B8: Team 2 – Jeem Boom Baa | C8: Amal
A9: 5 | B9: Team 3 – Dr. D | C9: Kevin
A10: 6 | B10: Team 3 – Dr. D | C10: Adwaith
A11: 7 | B11: Team 4 – Thoofan | C11: Sahil M I
A12: 8 | B12: Team 4 – Thoofan | C12: Rajeesh C V
A13: 9 | B13: Team 5 – Dhurandhar | C13: Adhith Vinoj
A14: 10 | B14: Team 5 – Dhurandhar | C14: Nidheesh P V
A15: 11 | B15: Team 6 – Aaram Thamburan | C15: Joel
A16: 12 | B16: Team 6 – Aaram Thamburan | C16: Jayesh
A18: Women’s Singles
A19: # | B19: Team | C19: Player 1 | E19: Notes
A20: 1 | B20: Team 1 – Rajarajeshwari United | C20: Neethu
A21: 2 | B21: Team 1 – Rajarajeshwari United | C21: Nivya
A22: 3 | B22: Team 2 – Jeem Boom Baa | C22: Tressy
A23: 4 | B23: Team 2 – Jeem Boom Baa | C23: Anima
A24: 5 | B24: Team 3 – Dr. D | C24: Anjaly
A25: 6 | B25: Team 3 – Dr. D | C25: Fadwah
A26: 7 | B26: Team 4 – Thoofan | C26: Gayathri
A27: 8 | B27: Team 4 – Thoofan | C27: AnnMary
A28: 9 | B28: Team 5 – Dhurandhar | C28: Sradha Santhosh
A29: 10 | B29: Team 5 – Dhurandhar | C29: Vidhya M Robert
A30: 11 | B30: Team 6 – Aaram Thamburan | C30: Merrin
A31: 12 | B31: Team 6 – Aaram Thamburan | C31: Akshaya
A33: Men’s Doubles
A34: # | B34: Team | C34: Player 1 | D34: Player 2 | E34: Notes
A35: 1 | B35: Team 1 – Rajarajeshwari United | C35: Amit | D35: Rishikesh
A36: 2 | B36: Team 1 – Rajarajeshwari United | C36: Joyel | D36: Jithu
A37: 3 | B37: Team 2 – Jeem Boom Baa | C37: Gokul | D37: Amal
A38: 4 | B38: Team 2 – Jeem Boom Baa | C38: Thomas | D38: Sravan
A39: 5 | B39: Team 3 – Dr. D | C39: Ashmil | D39: Jerishab
A40: 6 | B40: Team 3 – Dr. D | C40: Rithik | D40: Jerin
A41: 7 | B41: Team 4 – Thoofan | C41: Sahil M I | D41: Rajeesh C V
A42: 8 | B42: Team 4 – Thoofan | C42: Don | D42: Gautham
A43: 9 | B43: Team 5 – Dhurandhar | C43: Nidheesh P V | D43: Adhith Vinoj
...

Sheet Table Tennis
A1: Table Tennis – Entries
A3: Men’s Singles
A4: # | B4: Team | C4: Player 1 | E4: Notes
A5: 1 | B5: Team 1 – Rajarajeshwari United | C5: Rishikesh
A6: 2 | B6: Team 1 – Rajarajeshwari United | C6: Amit
A7: 3 | B7: Team 1 – Rajarajeshwari United | C7: Bilal
A8: 4 | B8: Team 1 – Rajarajeshwari United | C8: Deekshith
A9: 5 | B9: Team 1 – Rajarajeshwari United | C9: Joyel
A10: 6 | B10: Team 1 – Rajarajeshwari United | C10: Vidhu
A11: 7 | B11: Team 2 – Jeem Boom Baa | C11: Ray | E11: Listed as "Ray (Rayboy)"
A12: 8 | B12: Team 2 – Jeem Boom Baa | C12: Thomas
A13: 9 | B13: Team 3 – Dr. D | C13: Rithik
A14: 10 | B14: Team 3 – Dr. D | C14: Alwin
A15: 11 | B15: Team 3 – Dr. D | C15: Adwaith
A16: 12 | B16: Team 3 – Dr. D | C16: Prajith
A17: 13 | B17: Team 3 – Dr. D | C17: Nived
A18: 14 | B18: Team 4 – Thoofan | C18: Sahil M I
A19: 15 | B19: Team 4 – Thoofan | C19: Suryathejas | E19: Replaced Akhil P Jose (Thoofan request)
A20: 16 | B20: Team 4 – Thoofan | C20: Rajeesh C V
A21: 17 | B21: Team 4 – Thoofan | C21: Subin
A22: 18 | B22: Team 4 – Thoofan | C22: Arshal Abbas
A23: 19 | B23: Team 5 – Dhurandhar | C23: Nidheesh P V
A24: 20 | B24: Team 5 – Dhurandhar | C24: Abhishek P S
A25: 21 | B25: Team 6 – Aaram Thamburan | C25: Ansam
A26: 22 | B26: Team 6 – Aaram Thamburan | C26: Musthaq
A28: Women’s Singles
A29: # | B29: Team | C29: Player 1 | E29: Notes
A30: 1 | B30: Team 1 – Rajarajeshwari United | C30: Neethu
A31: 2 | B31: Team 1 – Rajarajeshwari United | C31: Nivya Mathew
A32: 3 | B32: Team 3 – Dr. D | C32: Anan
A33: 4 | B33: Team 4 – Thoofan | C33: Deepanjali
A34: 5 | B34: Team 4 – Thoofan | C34: Aparna
A35: 6 | B35: Team 5 – Dhurandhar | C35: Sradha Santhosh
A36: 7 | B36: Team 6 – Aaram Thamburan | C36: Akhila
A37: 8 | B37: Team 6 – Aaram Thamburan | C37: Ashna
A39: Men’s Doubles
A40: # | B40: Team | C40: Player 1 | D40: Player 2 | E40: Notes
A41: 1 | B41: Team 1 – Rajarajeshwari United | C41: Rishikesh | D41: Amit
A42: 2 | B42: Team 1 – Rajarajeshwari United | C42: Bilal | D42: Deekshith
A43: 3 | B43: Team 1 – Rajarajeshwari United | C43: Joyel | D43: Vidhu
...

Sheet Carrom
A1: Carrom – Entries
A3: Open Doubles
A4: # | B4: Team | C4: Player 1 | D4: Player 2 | E4: Notes
A5: 1 | B5: Team 1 – Rajarajeshwari United | C5: Joyel | D5: Shinu
A6: 2 | B6: Team 1 – Rajarajeshwari United | C6: Deekshith | D6: Akshay
A7: 3 | B7: Team 1 – Rajarajeshwari United | C7: Sharon | D7: Amit
A8: 4 | B8: Team 1 – Rajarajeshwari United | C8: Neethu | D8: Vidhu
A9: 5 | B9: Team 1 – Rajarajeshwari United | C9: Nivya | D9: Bilal
A10: 6 | B10: Team 1 – Rajarajeshwari United | C10: Jithu | D10: Bilsy
A11: 7 | B11: Team 1 – Rajarajeshwari United | C11: Nivya Peter | D11: Nikitha
A12: 8 | B12: Team 2 – Jeem Boom Baa | C12: Gokul | D12: Anurag
A13: 9 | B13: Team 2 – Jeem Boom Baa | C13: Ray | D13: Boban
A14: 10 | B14: Team 2 – Jeem Boom Baa | C14: Tressy | D14: Shijil
A15: 11 | B15: Team 2 – Jeem Boom Baa | C15: Athira | D15: Anas
A16: 12 | B16: Team 2 – Jeem Boom Baa | C16: Akshay | D16: Gouresh | E16: Listed as "Akshy - Guresh"
A17: 13 | B17: Team 3 – Dr. D | C17: Alwin | D17: Nived
A18: 14 | B18: Team 3 – Dr. D | C18: Ashmil | D18: Prajith
A19: 15 | B19: Team 3 – Dr. D | C19: Anan | D19: Avani
A20: 16 | B20: Team 3 – Dr. D | C20: Nandana | D20: Sona
A21: 17 | B21: Team 4 – Thoofan | C21: Rajeesh C V | D21: Ibrahim
A22: 18 | B22: Team 4 – Thoofan | C22: Aparna | D22: Sahil M I
A23: 19 | B23: Team 4 – Thoofan | C23: Gautham | D23: Don
A24: 20 | B24: Team 4 – Thoofan | C24: Deepanjali | D24: Anjana
A25: 21 | B25: Team 4 – Thoofan | C25: Samin | D25: Nikhil | E25: Replaced Sijin Jacob (Thoofan request)
A26: 22 | B26: Team 5 – Dhurandhar | C26: Sradha Santhosh | D26: Nidheesh P V
A27: 23 | B27: Team 5 – Dhurandhar | C27: Abhishek P S | D27: Vidhya M Robert
A28: 24 | B28: Team 5 – Dhurandhar | C28: Sarath Joseph | D28: Adhith Vinoj
A29: 25 | B29: Team 5 – Dhurandhar | C29: Abhijith K V | D29: Divin
A30: 26 | B30: Team 6 – Aaram Thamburan | C30: Merrin | D30: Anandhakrishnan
A31: 27 | B31: Team 6 – Aaram Thamburan | C31: Ansam | D31: Justin
A32: 28 | B32: Team 6 – Aaram Thamburan | C32: Sharan | D32: Musthaq
A33: 29 | B33: Team 6 – Aaram Thamburan | C33: Akhila | D33: Athira
A34: 30 | B34: Team 6 – Aaram Thamburan | C34: Hrishikesh | D34: Jayakrishnan
A35: 31 | B35: Team 6 – Aaram Thamburan | C35: Niju | D35: Christo

Sheet Chess
A1: Chess – Entries
A3: Men’s Singles
A4: # | B4: Team | C4: Player 1 | E4: Notes
A5: 1 | B5: Team 5 – Dhurandhar | C5: Nidheesh P V
A6: 2 | B6: Team 5 – Dhurandhar | C6: Akshay A
A7: 3 | B7: Team 5 – Dhurandhar | C7: Bhadresh Das
A8: 4 | B8: Team 5 – Dhurandhar | C8: Abhijith K V
A10: Women’s Singles
A11: # | B11: Team | C11: Player 1 | E11: Notes
A12: 1 | B12: Team 5 – Dhurandhar | C12: Sradha Santhosh
A13: 2 | B13: Team 5 – Dhurandhar | C13: Mary Metilda
A15: Open Singles
A16: # | B16: Team | C16: Player 1 | E16: Notes
A17: 1 | B17: Team 1 – Rajarajeshwari United | C17: Solomon
A18: 2 | B18: Team 1 – Rajarajeshwari United | C18: Nivya
A19: 3 | B19: Team 1 – Rajarajeshwari United | C19: Jithu
A20: 4 | B20: Team 1 – Rajarajeshwari United | C20: Shamil
A21: 5 | B21: Team 2 – Jeem Boom Baa | C21: Shijil
A22: 6 | B22: Team 2 – Jeem Boom Baa | C22: Bonny
A23: 7 | B23: Team 2 – Jeem Boom Baa | C23: Sravan
A24: 8 | B24: Team 2 – Jeem Boom Baa | C24: Anurag
A25: 9 | B25: Team 2 – Jeem Boom Baa | C25: Renson
A26: 10 | B26: Team 2 – Jeem Boom Baa | C26: Sainal
A27: 11 | B27: Team 2 – Jeem Boom Baa | C27: Gokul
A28: 12 | B28: Team 2 – Jeem Boom Baa | C28: Ray
... A34: 18 | B34: Team 4 – Thoofan | C34: Rajeesh C V
A35: 19 | B35: Team 4 – Thoofan | C35: Gautham | E35: Replaced Sijin Jacob (Thoofan request)
A36: 20 | B36: Team 4 – Thoofan | C36: AnnMary
A37: 21 | B37: Team 6 – Aaram Thamburan | C37: Akshaya
A38: 22 | B38: Team 6 – Aaram Thamburan | C38: Merrin
A39: 23 | B39: Team 6 – Aaram Thamburan | C39: Benison
A40: 24 | B40: Team 6 – Aaram Thamburan | C40: Hrishikesh
A41: 25 | B41: Team 6 – Aaram Thamburan | C41: Neha
